Workbook
Name subscribers_per_cbo: 'Assumptions'!$C$7
Name checkins_per_year: 'Assumptions'!$C$8
Name opening_segments: 'Assumptions'!$C$9
Name followup_segments: 'Assumptions'!$C$10
Name inbound_segments_if_complete: 'Assumptions'!$C$11
Name completion_rate: 'Assumptions'!$C$12
Name pages_per_cbo_month: 'Assumptions'!$C$15
Name refresh_days: 'Assumptions'!$C$16
Name searches_per_refresh: 'Assumptions'!$C$17
Name storage_mb_per_cbo: 'Assumptions'!$C$18
Name cbo_http_requests: 'Assumptions'!$C$19
Name geocode_updates_per_cbo: 'Assumptions'!$C$20
Name firestore_writes_per_cbo: 'Assumptions'!$C$21
Name firestore_reads_per_cbo: 'Assumptions'!$C$22
Name claude_per_cbo: 'Assumptions'!$C$23
Name map_loads_per_funder: 'Assumptions'!$C$26
Name ai_searches_per_funder: 'Assumptions'!$C$27
Name questions_per_funder: 'Assumptions'!$C$28
Name audits_per_funder: 'Assumptions'!$C$29
Name searches_per_audit: 'Assumptions'!$C$30
Name funder_http_requests: 'Assumptions'!$C$31
Name egress_mb_per_funder: 'Assumptions'!$C$32
Name doc_input_tokens: 'Assumptions'!$C$35
Name doc_output_tokens: 'Assumptions'!$C$36
Name research_input_tokens: 'Assumptions'!$C$37
Name research_output_tokens: 'Assumptions'!$C$38
Name interpret_input_tokens: 'Assumptions'!$C$39
Name interpret_output_tokens: 'Assumptions'!$C$40
Name rank_input_tokens: 'Assumptions'!$C$41
Name rank_output_tokens: 'Assumptions'!$C$42
Name question_input_tokens: 'Assumptions'!$C$43
Name question_output_tokens: 'Assumptions'!$C$44
Name sms_input_tokens: 'Assumptions'!$C$45
Name sms_output_tokens: 'Assumptions'!$C$46
Name sms_ai_share: 'Assumptions'!$C$47
Name audit_input_tokens: 'Assumptions'!$C$48
Name audit_output_tokens: 'Assumptions'!$C$49
Name page_vcpu_seconds: 'Assumptions'!$C$50
Name request_vcpu_seconds: 'Assumptions'!$C$51
Name memory_gib: 'Assumptions'!$C$52
Name min_instances: 'Assumptions'!$C$53
Name price_kenya_sms: 'Assumptions'!$C$56
Name price_inbound_sms: 'Assumptions'!$C$57
Name price_phone_number: 'Assumptions'!$C$58
Name phone_numbers: 'Assumptions'!$C$59
Name price_azure_page: 'Assumptions'!$C$60
Name price_gemini_in: 'Assumptions'!$C$61
Name price_gemini_out: 'Assumptions'!$C$62
Name price_openai_in: 'Assumptions'!$C$63
Name price_openai_out: 'Assumptions'!$C$64
Name price_search_1k: 'Assumptions'!$C$65
Name price_map_1k: 'Assumptions'!$C$66
Name price_geocode_1k: 'Assumptions'!$C$67
Name price_storage_gb: 'Assumptions'!$C$68
Name price_egress_gb: 'Assumptions'!$C$69
Name price_vcpu: 'Assumptions'!$C$70
Name price_gib: 'Assumptions'!$C$71
Name price_million_requests: 'Assumptions'!$C$72
Name price_warm_instance: 'Assumptions'!$C$73
Name price_sql_micro: 'Assumptions'!$C$74

Sheet Overview
A1: Kumbu Connect cost projections
A2: Live production, hosted and running. CBO signup is a Google Form or the in-app form, plus one short SMS link (about $0.31, or $0 with a QR code). That saving is on the One-time setup sheet. The monthly totals below are mostly community check-in texts, and those are unchanged. Yellow cells on Assumptions are the only inputs.
A4: Open a sheet
A5: Assumptions | B5: Change panel size, prices, pages, and tiers
A6: Unit costs | B6: What one more CBO costs, and one more funder
A7: Monthly matrix | B7: Full grid of CBO sizes by funder sizes
A8: Matched growth | B8: Both sides grow together, with a chart
A9: Sensitivity | B9: Monthly texts, larger panels, heavier Maps and AI
A10: One-time setup | B10: Cash to onboard up to each tier
A11: Notes | B11: What is included, what is free, what is left out
A13: The slope, at the default settings
A14: Platform floor, before usage | B14: =platform_floor_small | C14: Database plus number, secrets, and domain, while both sides are under 200.
A15: Each additional active CBO | B15: =variable_cost_per_cbo | C15: Almost entirely SMS to the community panel. Documents are a few cents.
A16: Each additional active funder | B16: =variable_cost_per_funder | C16: Search, questions, an occasional audit, and a little data transfer. The map is still free at these volumes.
A18: When both sides are the same size
A19: Active CBOs and funders | B19: Monthly | C19: Annual | D19: Per CBO | E19: SMS share | F19: Database | G19: SMS
A20: =cbo_tier_1 | B20: =SUMIFS(Scenarios!$V$6:$V$41,Scenarios!$A$6:$A$41,cbo_tier_1,Scenarios!$B$6:$B$41,cbo_tier_1) | C20: =B20*12 | D20: =IF(A20=0,NA(),B20/A20) | E20: =IF(B20=0,0,G20/B20) | F20: =SUMIFS(Scenarios!$C$6:$C$41,Scenarios!$A$6:$A$41,cbo_tier_1,Scenarios!$B$6:$B$41,cbo_tier_1) | G20: =(SUMIFS(Scenarios!$I$6:$I$41,Scenarios!$A$6:$A$41,cbo_tier_1,Scenarios!$B$6:$B$41,cbo_tier_1))+(SUMIFS(Scenarios!$J$6:$J$41,Scenarios!$A$6:$A$41,cbo_tier_1,Scenarios!$B$6:$B$41,cbo_tier_1))
A21: =cbo_tier_2 | B21: =SUMIFS(Scenarios!$V$6:$V$41,Scenarios!$A$6:$A$41,cbo_tier_2,Scenarios!$B$6:$B$41,cbo_tier_2) | C21: =B21*12 | D21: =IF(A21=0,NA(),B21/A21) | E21: =IF(B21=0,0,G21/B21) | F21: =SUMIFS(Scenarios!$C$6:$C$41,Scenarios!$A$6:$A$41,cbo_tier_2,Scenarios!$B$6:$B$41,cbo_tier_2) | G21: =(SUMIFS(Scenarios!$I$6:$I$41,Scenarios!$A$6:$A$41,cbo_tier_2,Scenarios!$B$6:$B$41,cbo_tier_2))+(SUMIFS(Scenarios!$J$6:$J$41,Scenarios!$A$6:$A$41,cbo_tier_2,Scenarios!$B$6:$B$41,cbo_tier_2))
A22: =cbo_tier_3 | B22: =SUMIFS(Scenarios!$V$6:$V$41,Scenarios!$A$6:$A$41,cbo_tier_3,Scenarios!$B$6:$B$41,cbo_tier_3) | C22: =B22*12 | D22: =IF(A22=0,NA(),B22/A22) | E22: =IF(B22=0,0,G22/B22) | F22: =SUMIFS(Scenarios!$C$6:$C$41,Scenarios!$A$6:$A$41,cbo_tier_3,Scenarios!$B$6:$B$41,cbo_tier_3) | G22: =(SUMIFS(Scenarios!$I$6:$I$41,Scenarios!$A$6:$A$41,cbo_tier_3,Scenarios!$B$6:$B$41,cbo_tier_3))+(SUMIFS(Scenarios!$J$6:$J$41,Scenarios!$A$6:$A$41,cbo_tier_3,Scenarios!$B$6:$B$41,cbo_tier_3))
A23: =cbo_tier_4 | B23: =SUMIFS(Scenarios!$V$6:$V$41,Scenarios!$A$6:$A$41,cbo_tier_4,Scenarios!$B$6:$B$41,cbo_tier_4) | C23: =B23*12 | D23: =IF(A23=0,NA(),B23/A23) | E23: =IF(B23=0,0,G23/B23) | F23: =SUMIFS(Scenarios!$C$6:$C$41,Scenarios!$A$6:$A$41,cbo_tier_4,Scenarios!$B$6:$B$41,cbo_tier_4) | G23: =(SUMIFS(Scenarios!$I$6:$I$41,Scenarios!$A$6:$A$41,cbo_tier_4,Scenarios!$B$6:$B$41,cbo_tier_4))+(SUMIFS(Scenarios!$J$6:$J$41,Scenarios!$A$6:$A$41,cbo_tier_4,Scenarios!$B$6:$B$41,cbo_tier_4))
A24: =cbo_tier_5 | B24: =SUMIFS(Scenarios!$V$6:$V$41,Scenarios!$A$6:$A$41,cbo_tier_5,Scenarios!$B$6:$B$41,cbo_tier_5) | C24: =B24*12 | D24: =IF(A24=0,NA(),B24/A24) | E24: =IF(B24=0,0,G24/B24) | F24: =SUMIFS(Scenarios!$C$6:$C$41,Scenarios!$A$6:$A$41,cbo_tier_5,Scenarios!$B$6:$B$41,cbo_tier_5) | G24: =(SUMIFS(Scenarios!$I$6:$I$41,Scenarios!$A$6:$A$41,cbo_tier_5,Scenarios!$B$6:$B$41,cbo_tier_5))+(SUMIFS(Scenarios!$J$6:$J$41,Scenarios!$A$6:$A$41,cbo_tier_5,Scenarios!$B$6:$B$41,cbo_tier_5))
A25: =cbo_tier_6 | B25: =SUMIFS(Scenarios!$V$6:$V$41,Scenarios!$A$6:$A$41,cbo_tier_6,Scenarios!$B$6:$B$41,cbo_tier_6) | C25: =B25*12 | D25: =IF(A25=0,NA(),B25/A25) | E25: =IF(B25=0,0,G25/B25) | F25: =SUMIFS(Scenarios!$C$6:$C$41,Scenarios!$A$6:$A$41,cbo_tier_6,Scenarios!$B$6:$B$41,cbo_tier_6) | G25: =(SUMIFS(Scenarios!$I$6:$I$41,Scenarios!$A$6:$A$41,cbo_tier_6,Scenarios!$B$6:$B$41,cbo_tier_6))+(SUMIFS(Scenarios!$J$6:$J$41,Scenarios!$A$6:$A$41,cbo_tier_6,Scenarios!$B$6:$B$41,cbo_tier_6))
A27: Monthly cost for every mix of CBOs and funders
A28: Active funders → | B28: =funder_tier_1 | C28: =funder_tier_2 | D28: =funder_tier_3 | E28: =funder_tier_4 | F28: =funder_tier_5 | G28: =funder_tier_6
A29: =cbo_tier_1 | B29: =SUMIFS(Scenarios!$V$6:$V$41,Scenarios!$A$6:$A$41,cbo_tier_1,Scenarios!$B$6:$B$41,funder_tier_1) | C29: =SUMIFS(Scenarios!$V$6:$V$41,Scenarios!$A$6:$A$41,cbo_tier_1,Scenarios!$B$6:$B$41,funder_tier_2) | D29: =SUMIFS(Scenarios!$V$6:$V$41,Scenarios!$A$6:$A$41,cbo_tier_1,Scenarios!$B$6:$B$41,funder_tier_3) | E29: =SUMIFS(Scenarios!$V$6:$V$41,Scenarios!$A$6:$A$41,cbo_tier_1,Scenarios!$B$6:$B$41,funder_tier_4) | F29: =SUMIFS(Scenarios!$V$6:$V$41,Scenarios!$A$6:$A$41,cbo_tier_1,Scenarios!$B$6:$B$41,funder_tier_5) | G29: =SUMIFS(Scenarios!$V$6:$V$41,Scenarios!$A$6:$A$41,cbo_tier_1,Scenarios!$B$6:$B$41,funder_tier_6)
A30: =cbo_tier_2 | B30: =SUMIFS(Scenarios!$V$6:$V$41,Scenarios!$A$6:$A$41,cbo_tier_2,Scenarios!$B$6:$B$41,funder_tier_1) | C30: =SUMIFS(Scenarios!$V$6:$V$41,Scenarios!$A$6:$A$41,cbo_tier_2,Scenarios!$B$6:$B$41,funder_tier_2) | D30: =SUMIFS(Scenarios!$V$6:$V$41,Scenarios!$A$6:$A$41,cbo_tier_2,Scenarios!$B$6:$B$41,funder_tier_3) | E30: =SUMIFS(Scenarios!$V$6:$V$41,Scenarios!$A$6:$A$41,cbo_tier_2,Scenarios!$B$6:$B$41,funder_tier_4) | F30: =SUMIFS(Scenarios!$V$6:$V$41,Scenarios!$A$6:$A$41,cbo_tier_2,Scenarios!$B$6:$B$41,funder_tier_5) | G30: =SUMIFS(Scenarios!$V$6:$V$41,Scenarios!$A$6:$A$41,cbo_tier_2,Scenarios!$B$6:$B$41,funder_tier_6)
A31: =cbo_tier_3 | B31: =SUMIFS(Scenarios!$V$6:$V$41,Scenarios!$A$6:$A$41,cbo_tier_3,Scenarios!$B$6:$B$41,funder_tier_1) | C31: =SUMIFS(Scenarios!$V$6:$V$41,Scenarios!$A$6:$A$41,cbo_tier_3,Scenarios!$B$6:$B$41,funder_tier_2) | D31: =SUMIFS(Scenarios!$V$6:$V$41,Scenarios!$A$6:$A$41,cbo_tier_3,Scenarios!$B$6:$B$41,funder_tier_3) | E31: =SUMIFS(Scenarios!$V$6:$V$41,Scenarios!$A$6:$A$41,cbo_tier_3,Scenarios!$B$6:$B$41,funder_tier_4) | F31: =SUMIFS(Scenarios!$V$6:$V$41,Scenarios!$A$6:$A$41,cbo_tier_3,Scenarios!$B$6:$B$41,funder_tier_5) | G31: =SUMIFS(Scenarios!$V$6:$V$41,Scenarios!$A$6:$A$41,cbo_tier_3,Scenarios!$B$6:$B$41,funder_tier_6)
A32: =cbo_tier_4 | B32: =SUMIFS(Scenarios!$V$6:$V$41,Scenarios!$A$6:$A$41,cbo_tier_4,Scenarios!$B$6:$B$41,funder_tier_1) | C32: =SUMIFS(Scenarios!$V$6:$V$41,Scenarios!$A$6:$A$41,cbo_tier_4,Scenarios!$B$6:$B$41,funder_tier_2) | D32: =SUMIFS(Scenarios!$V$6:$V$41,Scenarios!$A$6:$A$41,cbo_tier_4,Scenarios!$B$6:$B$41,funder_tier_3) | E32: =SUMIFS(Scenarios!$V$6:$V$41,Scenarios!$A$6:$A$41,cbo_tier_4,Scenarios!$B$6:$B$41,funder_tier_4) | F32: =SUMIFS(Scenarios!$V$6:$V$41,Scenarios!$A$6:$A$41,cbo_tier_4,Scenarios!$B$6:$B$41,funder_tier_5) | G32: =SUMIFS(Scenarios!$V$6:$V$41,Scenarios!$A$6:$A$41,cbo_tier_4,Scenarios!$B$6:$B$41,funder_tier_6)
A33: =cbo_tier_5 | B33: =SUMIFS(Scenarios!$V$6:$V$41,Scenarios!$A$6:$A$41,cbo_tier_5,Scenarios!$B$6:$B$41,funder_tier_1) | C33: =SUMIFS(Scenarios!$V$6:$V$41,Scenarios!$A$6:$A$41,cbo_tier_5,Scenarios!$B$6:$B$41,funder_tier_2) | D33: =SUMIFS(Scenarios!$V$6:$V$41,Scenarios!$A$6:$A$41,cbo_tier_5,Scenarios!$B$6:$B$41,funder_tier_3) | E33: =SUMIFS(Scenarios!$V$6:$V$41,Scenarios!$A$6:$A$41,cbo_tier_5,Scenarios!$B$6:$B$41,funder_tier_4) | F33: =SUMIFS(Scenarios!$V$6:$V$41,Scenarios!$A$6:$A$41,cbo_tier_5,Scenarios!$B$6:$B$41,funder_tier_5) | G33: =SUMIFS(Scenarios!$V$6:$V$41,Scenarios!$A$6:$A$41,cbo_tier_5,Scenarios!$B$6:$B$41,funder_tier_6)
A34: =cbo_tier_6 | B34: =SUMIFS(Scenarios!$V$6:$V$41,Scenarios!$A$6:$A$41,cbo_tier_6,Scenarios!$B$6:$B$41,funder_tier_1) | C34: =SUMIFS(Scenarios!$V$6:$V$41,Scenarios!$A$6:$A$41,cbo_tier_6,Scenarios!$B$6:$B$41,funder_tier_2) | D34: =SUMIFS(Scenarios!$V$6:$V$41,Scenarios!$A$6:$A$41,cbo_tier_6,Scenarios!$B$6:$B$41,funder_tier_3) | E34: =SUMIFS(Scenarios!$V$6:$V$41,Scenarios!$A$6:$A$41,cbo_tier_6,Scenarios!$B$6:$B$41,funder_tier_4) | F34: =SUMIFS(Scenarios!$V$6:$V$41,Scenarios!$A$6:$A$41,cbo_tier_6,Scenarios!$B$6:$B$41,funder_tier_5) | G34: =SUMIFS(Scenarios!$V$6:$V$41,Scenarios!$A$6:$A$41,cbo_tier_6,Scenarios!$B$6:$B$41,funder_tier_6)
A36: How the costs combine
A37: The two sides mostly add. They do not multiply. A large funder base does not make community SMS more expensive, and a large CBO base does not make map loads more expensive. They meet in two places: the database steps up when either side reaches 200, and again at 500, and a few shared allowances (Maps, web search, Cloud Run) are project-wide. Down a column, the bill follows CBOs because of texts to Kenya. Across a row, it stays nearly flat until the funder count crosses a database step. Cost per CBO starts higher at 10 organizations, because the database is a fixed bill, then settles close to the SMS cost per organization. The Sensitivity sheet is where the total stops being modest: monthly check-ins, or a much larger texting panel, multiply the SMS line. Heavier Gemini pricing and busier map use move it much less.

Sheet Assumptions
B1: Assumptions
B2: Yellow cells are the only inputs. Every other sheet reads these values. Tiers are active users in a month, not registered-but-idle accounts.
B4: Input | C4: Value | D4: Unit | E4: What it means
B6: Community SMS
B7: Community texters per CBO | C7: 8 | D7: people | E7: A feedback panel, not every beneficiary. Each person is eligible for the twice-yearly check-in.
B8: Check-ins per texter per year | C8: 2 | D8: campaigns / year | E8: Matches the app: one check-in every 6 months. Monthly check-ins are modeled on Sensitivity.
B9: Opening texts per check-in | C9: 1 | D9: SMS segments | E9: Sent to every texter, even if they never reply. Assumes the prompt fits in one 160-character segment.
B10: Follow-up texts if they finish | C10: 3 | D10: SMS segments | E10: Help-count question, story question, and thank-you. Charged only when someone completes the cycle.
B11: Replies if they finish | C11: 3 | D11: SMS segments | E11: Rating, count, and story coming back to the US number.
B12: Share who finish a check-in | C12: 0.55 | D12: of texters | E12: Everyone else costs only the opening text.
B14: CBO activity each month
B15: Document pages processed | C15: 3 | D15: pages / CBO | E15: Ongoing bookkeeping. The first-time backlog is on One-time setup.
B16: Public-web research interval | C16: 45 | D16: days | E16: The app refreshes a CBO about every 45 days, not on every funder search.
B17: Web searches per refresh | C17: 2 | D17: queries | E17: Results are cached. 100 Google queries a day are free.
B18: Stored files per CBO | C18: 60 | D18: MB | E18: Uploads and photos. The first 5 GB on the project is treated as included.
B19: App requests per CBO | C19: 40 | D19: requests | E19: Logins, saves, and page views. Used for the Cloud Run estimate.
B20: Address changes | C20: 0.02 | D20: per CBO / month | E20: The pin is stored after the first lookup.
B21: Firestore writes | C21: 25 | D21: writes / CBO | E21: Mirrors of SMS and bookkeeping. Free tier covers this through 500 CBOs.
B22: Firestore reads | C22: 50 | D22: reads / CBO | E22: Free tier is 50,000 reads a day.
B23: Optional Claude spend | C23: 0 | D23: USD / CBO / month | E23: Zero keeps the legacy Claude profile step off. Enter a dollar amount to include it.
B25: Funder activity each month
B26: Marketplace map loads | C26: 6 | D26: loads / funder | E26: One load per visit, about weekly. First 10,000 loads a month are free.
B27: AI marketplace searches | C27: 3 | D27: searches / funder | E27: Two model calls each, ranking a shortlist rather than every CBO.
B28: Questions about a CBO | C28: 1 | D28: questions / funder | E28: Asked of a profile that is already on the platform.
B29: Funding-audit checks | C29: 0.2 | D29: audits / funder | E29: About one OpenAI document check per funder every five months.
B30: Web searches per audit | C30: 1 | D30: queries | E30: A single confirmation search, not a fresh crawl.
B31: App requests per funder | C31: 24 | D31: requests | E31: Marketplace, profiles, and in-app messages. Those messages are not SMS.
B32: Data downloaded | C32: 20 | D32: MB / funder | E32: Pages and photos from the US region, with browser caching.
B34: Work done on each model or document call
B35: Document page, input tokens | C35: 4000 | D35: tokens | E35: Gemini normalizes Azure's transcription. It does not re-read the whole scan as the primary path.
B36: Document page, output tokens | C36: 1500 | D36: tokens | E36: Structured rows.
B37: Web-research input tokens | C37: 4500 | D37: tokens | E37: A few page excerpts.
B38: Web-research output tokens | C38: 900 | D38: tokens | E38: Short claims for the CBO to confirm.
B39: Search interpret, input tokens | C39: 1200 | D39: tokens
B40: Search interpret, output tokens | C40: 350 | D40: tokens
B41: Search rank, input tokens | C41: 5000 | D41: tokens | E41: Shortlist only. This cap is what stops funder search from getting expensive as CBOs grow.
B42: Search rank, output tokens | C42: 700 | D42: tokens
B43: CBO question, input tokens | C43: 2500 | D43: tokens
B44: CBO question, output tokens | C44: 500 | D44: tokens
B45: SMS parse, input tokens | C45: 600 | D45: tokens
...

Sheet Unit costs
B1: Unit costs
B2: These are calculated from Assumptions. They explain the slope of the bill. Shared free tiers are applied later, once per scenario, so they are not subtracted here.
B4: Per active CBO, each month
B5: Outbound SMS segments | C5: =subscribers_per_cbo*(checkins_per_year/12)*(opening_segments+followup_segments*completion_rate) | D5: Opening text for everyone, plus the three follow-ups only for people who finish.
B6: Inbound SMS segments | C6: =subscribers_per_cbo*(checkins_per_year/12)*inbound_segments_if_complete*completion_rate | D6: Replies from people who finish.
B7: Outbound SMS | C7: =sms_out_segments_per_cbo*price_kenya_sms | D7: This is the main per-CBO cost.
B8: Inbound SMS | C8: =sms_in_segments_per_cbo*price_inbound_sms | D8: Small, because replies hit a US number.
B9: Azure document reading | C9: =pages_per_cbo_month*price_azure_page | D9: Layout price per page times monthly pages.
B10: Gemini per document page | C10: =(doc_input_tokens/1000000)*price_gemini_in+(doc_output_tokens/1000000)*price_gemini_out | D10: Token price for one normalized page.
B11: Gemini on monthly documents | C11: =pages_per_cbo_month*gemini_doc_cost_per_page
B12: Research refreshes | C12: =30/refresh_days | D12: Share of CBOs refreshed in a typical month.
B13: Gemini on web research | C13: =refreshes_per_cbo_month*((research_input_tokens/1000000)*price_gemini_in+(research_output_tokens/1000000)*price_gemini_out) | D13: Does not include Google query fees. Those are shared and usually still free.
B14: Gemini on SMS replies | C14: =sms_in_segments_per_cbo*sms_ai_share*((sms_input_tokens/1000000)*price_gemini_in+(sms_output_tokens/1000000)*price_gemini_out) | D14: Only the share of replies marked as needing the model.
B15: Optional Claude | C15: =claude_per_cbo | D15: Zero unless you type a value on Assumptions.
B16: Variable cost of one more active CBO | C16: =sms_out_cost_per_cbo+sms_in_cost_per_cbo+azure_cost_per_cbo+gemini_doc_cost_per_cbo+gemini_research_cost_per_cbo+gemini_sms_cost_per_cbo+claude_cost_per_cbo | D16: Added every month. Storage, Firestore, Maps, and Cloud Run are extra only after a free allowance is used up.
B18: Per active funder, each month
B19: Gemini per marketplace search | C19: =((interpret_input_tokens+rank_input_tokens)/1000000)*price_gemini_in+((interpret_output_tokens+rank_output_tokens)/1000000)*price_gemini_out | D19: Interpret plus a capped ranking call.
B20: Gemini on that funder's searches | C20: =ai_searches_per_funder*gemini_cost_per_search
B21: Gemini on questions | C21: =questions_per_funder*((question_input_tokens/1000000)*price_gemini_in+(question_output_tokens/1000000)*price_gemini_out)
B22: OpenAI funding audits | C22: =audits_per_funder*((audit_input_tokens/1000000)*price_openai_in+(audit_output_tokens/1000000)*price_openai_out)
B23: Data transfer | C23: =(egress_mb_per_funder/1024)*price_egress_gb | D23: Before any included transfer, which this model sets at zero.
B24: Variable cost of one more active funder | C24: =gemini_search_cost_per_funder+gemini_question_cost_per_funder+openai_cost_per_funder+egress_cost_per_funder | D24: Map loads are free until the project passes 10,000 a month, so they are not in this slope.
B26: Platform floor, before usage
B27: Fixed fees | C27: =price_secrets+price_misc+price_phone_number*phone_numbers | D27: Number rental, secrets, domain, and a log buffer. Does not change with users.
B28: Floor while both sides are under the medium-database step | C28: =price_sql_micro+platform_fixed_fees+min_instances*price_warm_instance | D28: What you pay in a quiet month before SMS and documents.
B30: One-time cost to bring one CBO online
B31: Onboarding SMS | C31: =onboard_segments*price_kenya_sms | D31: One link text to the CBO leader. The form itself has no per-signup fee.
B32: First document batch | C32: =initial_pages*(price_azure_page+gemini_doc_cost_per_page) | D32: Azure plus Gemini for the signup backlog.
B33: First web-research pass | C33: =(research_input_tokens/1000000)*price_gemini_in+(research_output_tokens/1000000)*price_gemini_out | D33: Google queries for a few hundred signups still sit inside the free search quota.
B34: One-time total per new CBO | C34: =onboard_sms_per_cbo+initial_docs_per_cbo+initial_research_per_cbo | D34: Paid when they join. It does not repeat. The monthly cost starts on top of this.
B36: A quick reading: monthly cost is about the floor for that database size, plus the per-CBO amount times CBOs, plus the per-funder amount times funders. The scenario sheets are exact, because they also apply free tiers and the database step.

Sheet Scenarios
A1: Every combination
A2: One row is one live month at that size. Totals sum the component columns. Change a yellow input and this table follows.
A4: Scale | C4: Hosting | I4: SMS | K4: Documents and research | N4: Funder intelligence | S4: Maps and search | V4: Totals | AA4: Allowance used
A5: Active CBOs | B5: Active funders | C5: Database | D5: Fixed fees | E5: Cloud Run | F5: File storage | G5: Data transfer | H5: Firestore | I5: SMS to Kenya | J5: SMS replies | K5: Azure pages | L5: Gemini documents | M5: Gemini research | N5: Gemini search | O5: Gemini questions | P5: Gemini SMS | Q5: OpenAI audits | R5: Claude | S5: Web search | T5: Map loads | U5: Geocoding | V5: Monthly total | W5: Annual total | X5: Per CBO | Y5: SMS share | Z5: Hosting share | AA5: Map loads used | AB5: Search queries | AC5: vCPU-seconds | AD5: vCPU left in free tier
A6: =cbo_tier_1 | B6: =funder_tier_1 | C6: =IF(OR(A6>=step_std_at,B6>=step_std_at),price_sql_std,IF(OR(A6>=step_small_at,B6>=step_small_at),price_sql_small,price_sql_micro)) | D6: =platform_fixed_fees | E6: =MAX(0,AC6-free_vcpu)*price_vcpu+MAX(0,AC6*memory_gib-free_gib)*price_gib+MAX(0,(A6*cbo_http_requests+B6*funder_http_requests+A6*sms_in_segments_per_cbo)-free_requests)/1000000*price_million_requests+min_instances*price_warm_instance | F6: =MAX(0,A6*storage_mb_per_cbo/1024-free_storage_gb)*price_storage_gb | G6: =MAX(0,B6*egress_mb_per_funder/1024-free_egress_gb)*price_egress_gb | H6: =MAX(0,A6*firestore_writes_per_cbo-free_fs_writes)/100000*price_fs_write+MAX(0,A6*firestore_reads_per_cbo-free_fs_reads)/100000*price_fs_read | I6: =A6*sms_out_cost_per_cbo | J6: =A6*sms_in_cost_per_cbo | K6: =A6*azure_cost_per_cbo | L6: =A6*gemini_doc_cost_per_cbo | M6: =A6*gemini_research_cost_per_cbo | N6: =B6*gemini_search_cost_per_funder | O6: =B6*gemini_question_cost_per_funder | P6: =A6*gemini_sms_cost_per_cbo | Q6: =B6*openai_cost_per_funder | R6: =A6*claude_cost_per_cbo | S6: =MAX(0,AB6-free_search)/1000*price_search_1k | T6: =MAX(0,AA6-free_maps)/1000*price_map_1k | U6: =MAX(0,A6*geocode_updates_per_cbo-free_geocode)/1000*price_geocode_1k | V6: =SUM(C6:U6) | W6: =V6*12 | X6: =IF(A6=0,NA(),V6/A6) | Y6: =IF(V6=0,0,(I6+J6)/V6) | Z6: =IF(V6=0,0,SUM(C6:H6)/V6) | AA6: =B6*map_loads_per_funder | AB6: =A6*refreshes_per_cbo_month*searches_per_refresh+B6*audits_per_funder*searches_per_audit | AC6: =(A6*cbo_http_requests+B6*funder_http_requests+A6*sms_in_segments_per_cbo)*request_vcpu_seconds+A6*pages_per_cbo_month*page_vcpu_seconds | AD6: =free_vcpu-AC6
A7: =cbo_tier_1 | B7: =funder_tier_2 | C7: =IF(OR(A7>=step_std_at,B7>=step_std_at),price_sql_std,IF(OR(A7>=step_small_at,B7>=step_small_at),price_sql_small,price_sql_micro)) | D7: =platform_fixed_fees | E7: =MAX(0,AC7-free_vcpu)*price_vcpu+MAX(0,AC7*memory_gib-free_gib)*price_gib+MAX(0,(A7*cbo_http_requests+B7*funder_http_requests+A7*sms_in_segments_per_cbo)-free_requests)/1000000*price_million_requests+min_instances*price_warm_instance | F7: =MAX(0,A7*storage_mb_per_cbo/1024-free_storage_gb)*price_storage_gb | G7: =MAX(0,B7*egress_mb_per_funder/1024-free_egress_gb)*price_egress_gb | H7: =MAX(0,A7*firestore_writes_per_cbo-free_fs_writes)/100000*price_fs_write+MAX(0,A7*firestore_reads_per_cbo-free_fs_reads)/100000*price_fs_read | I7: =A7*sms_out_cost_per_cbo | J7: =A7*sms_in_cost_per_cbo | K7: =A7*azure_cost_per_cbo | L7: =A7*gemini_doc_cost_per_cbo | M7: =A7*gemini_research_cost_per_cbo | N7: =B7*gemini_search_cost_per_funder | O7: =B7*gemini_question_cost_per_funder | P7: =A7*gemini_sms_cost_per_cbo | Q7: =B7*openai_cost_per_funder | R7: =A7*claude_cost_per_cbo | S7: =MAX(0,AB7-free_search)/1000*price_search_1k | T7: =MAX(0,AA7-free_maps)/1000*price_map_1k | U7: =MAX(0,A7*geocode_updates_per_cbo-free_geocode)/1000*price_geocode_1k | V7: =SUM(C7:U7) | W7: =V7*12 | X7: =IF(A7=0,NA(),V7/A7) | Y7: =IF(V7=0,0,(I7+J7)/V7) | Z7: =IF(V7=0,0,SUM(C7:H7)/V7) | AA7: =B7*map_loads_per_funder | AB7: =A7*refreshes_per_cbo_month*searches_per_refresh+B7*audits_per_funder*searches_per_audit | AC7: =(A7*cbo_http_requests+B7*funder_http_requests+A7*sms_in_segments_per_cbo)*request_vcpu_seconds+A7*pages_per_cbo_month*page_vcpu_seconds | AD7: =free_vcpu-AC7
A8: =cbo_tier_1 | B8: =funder_tier_3 | C8: =IF(OR(A8>=step_std_at,B8>=step_std_at),price_sql_std,IF(OR(A8>=step_small_at,B8>=step_small_at),price_sql_small,price_sql_micro)) | D8: =platform_fixed_fees | E8: =MAX(0,AC8-free_vcpu)*price_vcpu+MAX(0,AC8*memory_gib-free_gib)*price_gib+MAX(0,(A8*cbo_http_requests+B8*funder_http_requests+A8*sms_in_segments_per_cbo)-free_requests)/1000000*price_million_requests+min_instances*price_warm_instance | F8: =MAX(0,A8*storage_mb_per_cbo/1024-free_storage_gb)*price_storage_gb | G8: =MAX(0,B8*egress_mb_per_funder/1024-free_egress_gb)*price_egress_gb | H8: =MAX(0,A8*firestore_writes_per_cbo-free_fs_writes)/100000*price_fs_write+MAX(0,A8*firestore_reads_per_cbo-free_fs_reads)/100000*price_fs_read | I8: =A8*sms_out_cost_per_cbo | J8: =A8*sms_in_cost_per_cbo | K8: =A8*azure_cost_per_cbo | L8: =A8*gemini_doc_cost_per_cbo | M8: =A8*gemini_research_cost_per_cbo | N8: =B8*gemini_search_cost_per_funder | O8: =B8*gemini_question_cost_per_funder | P8: =A8*gemini_sms_cost_per_cbo | Q8: =B8*openai_cost_per_funder | R8: =A8*claude_cost_per_cbo | S8: =MAX(0,AB8-free_search)/1000*price_search_1k | T8: =MAX(0,AA8-free_maps)/1000*price_map_1k | U8: =MAX(0,A8*geocode_updates_per_cbo-free_geocode)/1000*price_geocode_1k | V8: =SUM(C8:U8) | W8: =V8*12 | X8: =IF(A8=0,NA(),V8/A8) | Y8: =IF(V8=0,0,(I8+J8)/V8) | Z8: =IF(V8=0,0,SUM(C8:H8)/V8) | AA8: =B8*map_loads_per_funder | AB8: =A8*refreshes_per_cbo_month*searches_per_refresh+B8*audits_per_funder*searches_per_audit | AC8: =(A8*cbo_http_requests+B8*funder_http_requests+A8*sms_in_segments_per_cbo)*request_vcpu_seconds+A8*pages_per_cbo_month*page_vcpu_seconds | AD8: =free_vcpu-AC8
A9: =cbo_tier_1 | B9: =funder_tier_4 | C9: =IF(OR(A9>=step_std_at,B9>=step_std_at),price_sql_std,IF(OR(A9>=step_small_at,B9>=step_small_at),price_sql_small,price_sql_micro)) | D9: =platform_fixed_fees | E9: =MAX(0,AC9-free_vcpu)*price_vcpu+MAX(0,AC9*memory_gib-free_gib)*price_gib+MAX(0,(A9*cbo_http_requests+B9*funder_http_requests+A9*sms_in_segments_per_cbo)-free_requests)/1000000*price_million_requests+min_instances*price_warm_instance | F9: =MAX(0,A9*storage_mb_per_cbo/1024-free_storage_gb)*price_storage_gb | G9: =MAX(0,B9*egress_mb_per_funder/1024-free_egress_gb)*price_egress_gb | H9: =MAX(0,A9*firestore_writes_per_cbo-free_fs_writes)/100000*price_fs_write+MAX(0,A9*firestore_reads_per_cbo-free_fs_reads)/100000*price_fs_read | I9: =A9*sms_out_cost_per_cbo | J9: =A9*sms_in_cost_per_cbo | K9: =A9*azure_cost_per_cbo | L9: =A9*gemini_doc_cost_per_cbo | M9: =A9*gemini_research_cost_per_cbo | N9: =B9*gemini_search_cost_per_funder | O9: =B9*gemini_question_cost_per_funder | P9: =A9*gemini_sms_cost_per_cbo | Q9: =B9*openai_cost_per_funder | R9: =A9*claude_cost_per_cbo | S9: =MAX(0,AB9-free_search)/1000*price_search_1k | T9: =MAX(0,AA9-free_maps)/1000*price_map_1k | U9: =MAX(0,A9*geocode_updates_per_cbo-free_geocode)/1000*price_geocode_1k | V9: =SUM(C9:U9) | W9: =V9*12 | X9: =IF(A9=0,NA(),V9/A9) | Y9: =IF(V9=0,0,(I9+J9)/V9) | Z9: =IF(V9=0,0,SUM(C9:H9)/V9) | AA9: =B9*map_loads_per_funder | AB9: =A9*refreshes_per_cbo_month*searches_per_refresh+B9*audits_per_funder*searches_per_audit | AC9: =(A9*cbo_http_requests+B9*funder_http_requests+A9*sms_in_segments_per_cbo)*request_vcpu_seconds+A9*pages_per_cbo_month*page_vcpu_seconds | AD9: =free_vcpu-AC9
A10: =cbo_tier_1 | B10: =funder_tier_5 | C10: =IF(OR(A10>=step_std_at,B10>=step_std_at),price_sql_std,IF(OR(A10>=step_small_at,B10>=step_small_at),price_sql_small,price_sql_micro)) | D10: =platform_fixed_fees | E10: =MAX(0,AC10-free_vcpu)*price_vcpu+MAX(0,AC10*memory_gib-free_gib)*price_gib+MAX(0,(A10*cbo_http_requests+B10*funder_http_requests+A10*sms_in_segments_per_cbo)-free_requests)/1000000*price_million_requests+min_instances*price_warm_instance | F10: =MAX(0,A10*storage_mb_per_cbo/1024-free_storage_gb)*price_storage_gb | G10: =MAX(0,B10*egress_mb_per_funder/1024-free_egress_gb)*price_egress_gb | H10: =MAX(0,A10*firestore_writes_per_cbo-free_fs_writes)/100000*price_fs_write+MAX(0,A10*firestore_reads_per_cbo-free_fs_reads)/100000*price_fs_read | I10: =A10*sms_out_cost_per_cbo | J10: =A10*sms_in_cost_per_cbo | K10: =A10*azure_cost_per_cbo | L10: =A10*gemini_doc_cost_per_cbo | M10: =A10*gemini_research_cost_per_cbo | N10: =B10*gemini_search_cost_per_funder | O10: =B10*gemini_question_cost_per_funder | P10: =A10*gemini_sms_cost_per_cbo | Q10: =B10*openai_cost_per_funder | R10: =A10*claude_cost_per_cbo | S10: =MAX(0,AB10-free_search)/1000*price_search_1k | T10: =MAX(0,AA10-free_maps)/1000*price_map_1k | U10: =MAX(0,A10*geocode_updates_per_cbo-free_geocode)/1000*price_geocode_1k | V10: =SUM(C10:U10) | W10: =V10*12 | X10: =IF(A10=0,NA(),V10/A10) | Y10: =IF(V10=0,0,(I10+J10)/V10) | Z10: =IF(V10=0,0,SUM(C10:H10)/V10) | AA10: =B10*map_loads_per_funder | AB10: =A10*refreshes_per_cbo_month*searches_per_refresh+B10*audits_per_funder*searches_per_audit | AC10: =(A10*cbo_http_requests+B10*funder_http_requests+A10*sms_in_segments_per_cbo)*request_vcpu_seconds+A10*pages_per_cbo_month*page_vcpu_seconds | AD10: =free_vcpu-AC10
A11: =cbo_tier_1 | B11: =funder_tier_6 | C11: =IF(OR(A11>=step_std_at,B11>=step_std_at),price_sql_std,IF(OR(A11>=step_small_at,B11>=step_small_at),price_sql_small,price_sql_micro)) | D11: =platform_fixed_fees | E11: =MAX(0,AC11-free_vcpu)*price_vcpu+MAX(0,AC11*memory_gib-free_gib)*price_gib+MAX(0,(A11*cbo_http_requests+B11*funder_http_requests+A11*sms_in_segments_per_cbo)-free_requests)/1000000*price_million_requests+min_instances*price_warm_instance | F11: =MAX(0,A11*storage_mb_per_cbo/1024-free_storage_gb)*price_storage_gb | G11: =MAX(0,B11*egress_mb_per_funder/1024-free_egress_gb)*price_egress_gb | H11: =MAX(0,A11*firestore_writes_per_cbo-free_fs_writes)/100000*price_fs_write+MAX(0,A11*firestore_reads_per_cbo-free_fs_reads)/100000*price_fs_read | I11: =A11*sms_out_cost_per_cbo | J11: =A11*sms_in_cost_per_cbo | K11: =A11*azure_cost_per_cbo | L11: =A11*gemini_doc_cost_per_cbo | M11: =A11*gemini_research_cost_per_cbo | N11: =B11*gemini_search_cost_per_funder | O11: =B11*gemini_question_cost_per_funder | P11: =A11*gemini_sms_cost_per_cbo | Q11: =B11*openai_cost_per_funder | R11: =A11*claude_cost_per_cbo | S11: =MAX(0,AB11-free_search)/1000*price_search_1k | T11: =MAX(0,AA11-free_maps)/1000*price_map_1k | U11: =MAX(0,A11*geocode_updates_per_cbo-free_geocode)/1000*price_geocode_1k | V11: =SUM(C11:U11) | W11: =V11*12 | X11: =IF(A11=0,NA(),V11/A11) | Y11: =IF(V11=0,0,(I11+J11)/V11) | Z11: =IF(V11=0,0,SUM(C11:H11)/V11) | AA11: =B11*map_loads_per_funder | AB11: =A11*refreshes_per_cbo_month*searches_per_refresh+B11*audits_per_funder*searches_per_audit | AC11: =(A11*cbo_http_requests+B11*funder_http_requests+A11*sms_in_segments_per_cbo)*request_vcpu_seconds+A11*pages_per_cbo_month*page_vcpu_seconds | AD11: =free_vcpu-AC11
A12: =cbo_tier_2 | B12: =funder_tier_1 | C12: =IF(OR(A12>=step_std_at,B12>=step_std_at),price_sql_std,IF(OR(A12>=step_small_at,B12>=step_small_at),price_sql_small,price_sql_micro)) | D12: =platform_fixed_fees | E12: =MAX(0,AC12-free_vcpu)*price_vcpu+MAX(0,AC12*memory_gib-free_gib)*price_gib+MAX(0,(A12*cbo_http_requests+B12*funder_http_requests+A12*sms_in_segments_per_cbo)-free_requests)/1000000*price_million_requests+min_instances*price_warm_instance | F12: =MAX(0,A12*storage_mb_per_cbo/1024-free_storage_gb)*price_storage_gb | G12: =MAX(0,B12*egress_mb_per_funder/1024-free_egress_gb)*price_egress_gb | H12: =MAX(0,A12*firestore_writes_per_cbo-free_fs_writes)/100000*price_fs_write+MAX(0,A12*firestore_reads_per_cbo-free_fs_reads)/100000*price_fs_read | I12: =A12*sms_out_cost_per_cbo | J12: =A12*sms_in_cost_per_cbo | K12: =A12*azure_cost_per_cbo | L12: =A12*gemini_doc_cost_per_cbo | M12: =A12*gemini_research_cost_per_cbo | N12: =B12*gemini_search_cost_per_funder | O12: =B12*gemini_question_cost_per_funder | P12: =A12*gemini_sms_cost_per_cbo | Q12: =B12*openai_cost_per_funder | R12: =A12*claude_cost_per_cbo | S12: =MAX(0,AB12-free_search)/1000*price_search_1k | T12: =MAX(0,AA12-free_maps)/1000*price_map_1k | U12: =MAX(0,A12*geocode_updates_per_cbo-free_geocode)/1000*price_geocode_1k | V12: =SUM(C12:U12) | W12: =V12*12 | X12: =IF(A12=0,NA(),V12/A12) | Y12: =IF(V12=0,0,(I12+J12)/V12) | Z12: =IF(V12=0,0,SUM(C12:H12)/V12) | AA12: =B12*map_loads_per_funder | AB12: =A12*refreshes_per_cbo_month*searches_per_refresh+B12*audits_per_funder*searches_per_audit | AC12: =(A12*cbo_http_requests+B12*funder_http_requests+A12*sms_in_segments_per_cbo)*request_vcpu_seconds+A12*pages_per_cbo_month*page_vcpu_seconds | AD12: =free_vcpu-AC12
A13: =cbo_tier_2 | B13: =funder_tier_2 | C13: =IF(OR(A13>=step_std_at,B13>=step_std_at),price_sql_std,IF(OR(A13>=step_small_at,B13>=step_small_at),price_sql_small,price_sql_micro)) | D13: =platform_fixed_fees | E13: =MAX(0,AC13-free_vcpu)*price_vcpu+MAX(0,AC13*memory_gib-free_gib)*price_gib+MAX(0,(A13*cbo_http_requests+B13*funder_http_requests+A13*sms_in_segments_per_cbo)-free_requests)/1000000*price_million_requests+min_instances*price_warm_instance | F13: =MAX(0,A13*storage_mb_per_cbo/1024-free_storage_gb)*price_storage_gb | G13: =MAX(0,B13*egress_mb_per_funder/1024-free_egress_gb)*price_egress_gb | H13: =MAX(0,A13*firestore_writes_per_cbo-free_fs_writes)/100000*price_fs_write+MAX(0,A13*firestore_reads_per_cbo-free_fs_reads)/100000*price_fs_read | I13: =A13*sms_out_cost_per_cbo | J13: =A13*sms_in_cost_per_cbo | K13: =A13*azure_cost_per_cbo | L13: =A13*gemini_doc_cost_per_cbo | M13: =A13*gemini_research_cost_per_cbo | N13: =B13*gemini_search_cost_per_funder | O13: =B13*gemini_question_cost_per_funder | P13: =A13*gemini_sms_cost_per_cbo | Q13: =B13*openai_cost_per_funder | R13: =A13*claude_cost_per_cbo | S13: =MAX(0,AB13-free_search)/1000*price_search_1k | T13: =MAX(0,AA13-free_maps)/1000*price_map_1k | U13: =MAX(0,A13*geocode_updates_per_cbo-free_geocode)/1000*price_geocode_1k | V13: =SUM(C13:U13) | W13: =V13*12 | X13: =IF(A13=0,NA(),V13/A13) | Y13: =IF(V13=0,0,(I13+J13)/V13) | Z13: =IF(V13=0,0,SUM(C13:H13)/V13) | AA13: =B13*map_loads_per_funder | AB13: =A13*refreshes_per_cbo_month*searches_per_refresh+B13*audits_per_funder*searches_per_audit | AC13: =(A13*cbo_http_requests+B13*funder_http_requests+A13*sms_in_segments_per_cbo)*request_vcpu_seconds+A13*pages_per_cbo_month*page_vcpu_seconds | AD13: =free_vcpu-AC13
A14: =cbo_tier_2 | B14: =funder_tier_3 | C14: =IF(OR(A14>=step_std_at,B14>=step_std_at),price_sql_std,IF(OR(A14>=step_small_at,B14>=step_small_at),price_sql_small,price_sql_micro)) | D14: =platform_fixed_fees | E14: =MAX(0,AC14-free_vcpu)*price_vcpu+MAX(0,AC14*memory_gib-free_gib)*price_gib+MAX(0,(A14*cbo_http_requests+B14*funder_http_requests+A14*sms_in_segments_per_cbo)-free_requests)/1000000*price_million_requests+min_instances*price_warm_instance | F14: =MAX(0,A14*storage_mb_per_cbo/1024-free_storage_gb)*price_storage_gb | G14: =MAX(0,B14*egress_mb_per_funder/1024-free_egress_gb)*price_egress_gb | H14: =MAX(0,A14*firestore_writes_per_cbo-free_fs_writes)/100000*price_fs_write+MAX(0,A14*firestore_reads_per_cbo-free_fs_reads)/100000*price_fs_read | I14: =A14*sms_out_cost_per_cbo | J14: =A14*sms_in_cost_per_cbo | K14: =A14*azure_cost_per_cbo | L14: =A14*gemini_doc_cost_per_cbo | M14: =A14*gemini_research_cost_per_cbo | N14: =B14*gemini_search_cost_per_funder | O14: =B14*gemini_question_cost_per_funder | P14: =A14*gemini_sms_cost_per_cbo | Q14: =B14*openai_cost_per_funder | R14: =A14*claude_cost_per_cbo | S14: =MAX(0,AB14-free_search)/1000*price_search_1k | T14: =MAX(0,AA14-free_maps)/1000*price_map_1k | U14: =MAX(0,A14*geocode_updates_per_cbo-free_geocode)/1000*price_geocode_1k | V14: =SUM(C14:U14) | W14: =V14*12 | X14: =IF(A14=0,NA(),V14/A14) | Y14: =IF(V14=0,0,(I14+J14)/V14) | Z14: =IF(V14=0,0,SUM(C14:H14)/V14) | AA14: =B14*map_loads_per_funder | AB14: =A14*refreshes_per_cbo_month*searches_per_refresh+B14*audits_per_funder*searches_per_audit | AC14: =(A14*cbo_http_requests+B14*funder_http_requests+A14*sms_in_segments_per_cbo)*request_vcpu_seconds+A14*pages_per_cbo_month*page_vcpu_seconds | AD14: =free_vcpu-AC14
A15: =cbo_tier_2 | B15: =funder_tier_4 | C15: =IF(OR(A15>=step_std_at,B15>=step_std_at),price_sql_std,IF(OR(A15>=step_small_at,B15>=step_small_at),price_sql_small,price_sql_micro)) | D15: =platform_fixed_fees | E15: =MAX(0,AC15-free_vcpu)*price_vcpu+MAX(0,AC15*memory_gib-free_gib)*price_gib+MAX(0,(A15*cbo_http_requests+B15*funder_http_requests+A15*sms_in_segments_per_cbo)-free_requests)/1000000*price_million_requests+min_instances*price_warm_instance | F15: =MAX(0,A15*storage_mb_per_cbo/1024-free_storage_gb)*price_storage_gb | G15: =MAX(0,B15*egress_mb_per_funder/1024-free_egress_gb)*price_egress_gb | H15: =MAX(0,A15*firestore_writes_per_cbo-free_fs_writes)/100000*price_fs_write+MAX(0,A15*firestore_reads_per_cbo-free_fs_reads)/100000*price_fs_read | I15: =A15*sms_out_cost_per_cbo | J15: =A15*sms_in_cost_per_cbo | K15: =A15*azure_cost_per_cbo | L15: =A15*gemini_doc_cost_per_cbo | M15: =A15*gemini_research_cost_per_cbo | N15: =B15*gemini_search_cost_per_funder | O15: =B15*gemini_question_cost_per_funder | P15: =A15*gemini_sms_cost_per_cbo | Q15: =B15*openai_cost_per_funder | R15: =A15*claude_cost_per_cbo | S15: =MAX(0,AB15-free_search)/1000*price_search_1k | T15: =MAX(0,AA15-free_maps)/1000*price_map_1k | U15: =MAX(0,A15*geocode_updates_per_cbo-free_geocode)/1000*price_geocode_1k | V15: =SUM(C15:U15) | W15: =V15*12 | X15: =IF(A15=0,NA(),V15/A15) | Y15: =IF(V15=0,0,(I15+J15)/V15) | Z15: =IF(V15=0,0,SUM(C15:H15)/V15) | AA15: =B15*map_loads_per_funder | AB15: =A15*refreshes_per_cbo_month*searches_per_refresh+B15*audits_per_funder*searches_per_audit | AC15: =(A15*cbo_http_requests+B15*funder_http_requests+A15*sms_in_segments_per_cbo)*request_vcpu_seconds+A15*pages_per_cbo_month*page_vcpu_seconds | AD15: =free_vcpu-AC15
A16: =cbo_tier_2 | B16: =funder_tier_5 | C16: =IF(OR(A16>=step_std_at,B16>=step_std_at),price_sql_std,IF(OR(A16>=step_small_at,B16>=step_small_at),price_sql_small,price_sql_micro)) | D16: =platform_fixed_fees | E16: =MAX(0,AC16-free_vcpu)*price_vcpu+MAX(0,AC16*memory_gib-free_gib)*price_gib+MAX(0,(A16*cbo_http_requests+B16*funder_http_requests+A16*sms_in_segments_per_cbo)-free_requests)/1000000*price_million_requests+min_instances*price_warm_instance | F16: =MAX(0,A16*storage_mb_per_cbo/1024-free_storage_gb)*price_storage_gb | G16: =MAX(0,B16*egress_mb_per_funder/1024-free_egress_gb)*price_egress_gb | H16: =MAX(0,A16*firestore_writes_per_cbo-free_fs_writes)/100000*price_fs_write+MAX(0,A16*firestore_reads_per_cbo-free_fs_reads)/100000*price_fs_read | I16: =A16*sms_out_cost_per_cbo | J16: =A16*sms_in_cost_per_cbo | K16: =A16*azure_cost_per_cbo | L16: =A16*gemini_doc_cost_per_cbo | M16: =A16*gemini_research_cost_per_cbo | N16: =B16*gemini_search_cost_per_funder | O16: =B16*gemini_question_cost_per_funder | P16: =A16*gemini_sms_cost_per_cbo | Q16: =B16*openai_cost_per_funder | R16: =A16*claude_cost_per_cbo | S16: =MAX(0,AB16-free_search)/1000*price_search_1k | T16: =MAX(0,AA16-free_maps)/1000*price_map_1k | U16: =MAX(0,A16*geocode_updates_per_cbo-free_geocode)/1000*price_geocode_1k | V16: =SUM(C16:U16) | W16: =V16*12 | X16: =IF(A16=0,NA(),V16/A16) | Y16: =IF(V16=0,0,(I16+J16)/V16) | Z16: =IF(V16=0,0,SUM(C16:H16)/V16) | AA16: =B16*map_loads_per_funder | AB16: =A16*refreshes_per_cbo_month*searches_per_refresh+B16*audits_per_funder*searches_per_audit | AC16: =(A16*cbo_http_requests+B16*funder_http_requests+A16*sms_in_segments_per_cbo)*request_vcpu_seconds+A16*pages_per_cbo_month*page_vcpu_seconds | AD16: =free_vcpu-AC16
A17: =cbo_tier_2 | B17: =funder_tier_6 | C17: =IF(OR(A17>=step_std_at,B17>=step_std_at),price_sql_std,IF(OR(A17>=step_small_at,B17>=step_small_at),price_sql_small,price_sql_micro)) | D17: =platform_fixed_fees | E17: =MAX(0,AC17-free_vcpu)*price_vcpu+MAX(0,AC17*memory_gib-free_gib)*price_gib+MAX(0,(A17*cbo_http_requests+B17*funder_http_requests+A17*sms_in_segments_per_cbo)-free_requests)/1000000*price_million_requests+min_instances*price_warm_instance | F17: =MAX(0,A17*storage_mb_per_cbo/1024-free_storage_gb)*price_storage_gb | G17: =MAX(0,B17*egress_mb_per_funder/1024-free_egress_gb)*price_egress_gb | H17: =MAX(0,A17*firestore_writes_per_cbo-free_fs_writes)/100000*price_fs_write+MAX(0,A17*firestore_reads_per_cbo-free_fs_reads)/100000*price_fs_read | I17: =A17*sms_out_cost_per_cbo | J17: =A17*sms_in_cost_per_cbo | K17: =A17*azure_cost_per_cbo | L17: =A17*gemini_doc_cost_per_cbo | M17: =A17*gemini_research_cost_per_cbo | N17: =B17*gemini_search_cost_per_funder | O17: =B17*gemini_question_cost_per_funder | P17: =A17*gemini_sms_cost_per_cbo | Q17: =B17*openai_cost_per_funder | R17: =A17*claude_cost_per_cbo | S17: =MAX(0,AB17-free_search)/1000*price_search_1k | T17: =MAX(0,AA17-free_maps)/1000*price_map_1k | U17: =MAX(0,A17*geocode_updates_per_cbo-free_geocode)/1000*price_geocode_1k | V17: =SUM(C17:U17) | W17: =V17*12 | X17: =IF(A17=0,NA(),V17/A17) | Y17: =IF(V17=0,0,(I17+J17)/V17) | Z17: =IF(V17=0,0,SUM(C17:H17)/V17) | AA17: =B17*map_loads_per_funder | AB17: =A17*refreshes_per_cbo_month*searches_per_refresh+B17*audits_per_funder*searches_per_audit | AC17: =(A17*cbo_http_requests+B17*funder_http_requests+A17*sms_in_segments_per_cbo)*request_vcpu_seconds+A17*pages_per_cbo_month*page_vcpu_seconds | AD17: =free_vcpu-AC17
A18: =cbo_tier_3 | B18: =funder_tier_1 | C18: =IF(OR(A18>=step_std_at,B18>=step_std_at),price_sql_std,IF(OR(A18>=step_small_at,B18>=step_small_at),price_sql_small,price_sql_micro)) | D18: =platform_fixed_fees | E18: =MAX(0,AC18-free_vcpu)*price_vcpu+MAX(0,AC18*memory_gib-free_gib)*price_gib+MAX(0,(A18*cbo_http_requests+B18*funder_http_requests+A18*sms_in_segments_per_cbo)-free_requests)/1000000*price_million_requests+min_instances*price_warm_instance | F18: =MAX(0,A18*storage_mb_per_cbo/1024-free_storage_gb)*price_storage_gb | G18: =MAX(0,B18*egress_mb_per_funder/1024-free_egress_gb)*price_egress_gb | H18: =MAX(0,A18*firestore_writes_per_cbo-free_fs_writes)/100000*price_fs_write+MAX(0,A18*firestore_reads_per_cbo-free_fs_reads)/100000*price_fs_read | I18: =A18*sms_out_cost_per_cbo | J18: =A18*sms_in_cost_per_cbo | K18: =A18*azure_cost_per_cbo | L18: =A18*gemini_doc_cost_per_cbo | M18: =A18*gemini_research_cost_per_cbo | N18: =B18*gemini_search_cost_per_funder | O18: =B18*gemini_question_cost_per_funder | P18: =A18*gemini_sms_cost_per_cbo | Q18: =B18*openai_cost_per_funder | R18: =A18*claude_cost_per_cbo | S18: =MAX(0,AB18-free_search)/1000*price_search_1k | T18: =MAX(0,AA18-free_maps)/1000*price_map_1k | U18: =MAX(0,A18*geocode_updates_per_cbo-free_geocode)/1000*price_geocode_1k | V18: =SUM(C18:U18) | W18: =V18*12 | X18: =IF(A18=0,NA(),V18/A18) | Y18: =IF(V18=0,0,(I18+J18)/V18) | Z18: =IF(V18=0,0,SUM(C18:H18)/V18) | AA18: =B18*map_loads_per_funder | AB18: =A18*refreshes_per_cbo_month*searches_per_refresh+B18*audits_per_funder*searches_per_audit | AC18: =(A18*cbo_http_requests+B18*funder_http_requests+A18*sms_in_segments_per_cbo)*request_vcpu_seconds+A18*pages_per_cbo_month*page_vcpu_seconds | AD18: =free_vcpu-AC18
A19: =cbo_tier_3 | B19: =funder_tier_2 | C19: =IF(OR(A19>=step_std_at,B19>=step_std_at),price_sql_std,IF(OR(A19>=step_small_at,B19>=step_small_at),price_sql_small,price_sql_micro)) | D19: =platform_fixed_fees | E19: =MAX(0,AC19-free_vcpu)*price_vcpu+MAX(0,AC19*memory_gib-free_gib)*price_gib+MAX(0,(A19*cbo_http_requests+B19*funder_http_requests+A19*sms_in_segments_per_cbo)-free_requests)/1000000*price_million_requests+min_instances*price_warm_instance | F19: =MAX(0,A19*storage_mb_per_cbo/1024-free_storage_gb)*price_storage_gb | G19: =MAX(0,B19*egress_mb_per_funder/1024-free_egress_gb)*price_egress_gb | H19: =MAX(0,A19*firestore_writes_per_cbo-free_fs_writes)/100000*price_fs_write+MAX(0,A19*firestore_reads_per_cbo-free_fs_reads)/100000*price_fs_read | I19: =A19*sms_out_cost_per_cbo | J19: =A19*sms_in_cost_per_cbo | K19: =A19*azure_cost_per_cbo | L19: =A19*gemini_doc_cost_per_cbo | M19: =A19*gemini_research_cost_per_cbo | N19: =B19*gemini_search_cost_per_funder | O19: =B19*gemini_question_cost_per_funder | P19: =A19*gemini_sms_cost_per_cbo | Q19: =B19*openai_cost_per_funder | R19: =A19*claude_cost_per_cbo | S19: =MAX(0,AB19-free_search)/1000*price_search_1k | T19: =MAX(0,AA19-free_maps)/1000*price_map_1k | U19: =MAX(0,A19*geocode_updates_per_cbo-free_geocode)/1000*price_geocode_1k | V19: =SUM(C19:U19) | W19: =V19*12 | X19: =IF(A19=0,NA(),V19/A19) | Y19: =IF(V19=0,0,(I19+J19)/V19) | Z19: =IF(V19=0,0,SUM(C19:H19)/V19) | AA19: =B19*map_loads_per_funder | AB19: =A19*refreshes_per_cbo_month*searches_per_refresh+B19*audits_per_funder*searches_per_audit | AC19: =(A19*cbo_http_requests+B19*funder_http_requests+A19*sms_in_segments_per_cbo)*request_vcpu_seconds+A19*pages_per_cbo_month*page_vcpu_seconds | AD19: =free_vcpu-AC19
A20: =cbo_tier_3 | B20: =funder_tier_3 | C20: =IF(OR(A20>=step_std_at,B20>=step_std_at),price_sql_std,IF(OR(A20>=step_small_at,B20>=step_small_at),price_sql_small,price_sql_micro)) | D20: =platform_fixed_fees | E20: =MAX(0,AC20-free_vcpu)*price_vcpu+MAX(0,AC20*memory_gib-free_gib)*price_gib+MAX(0,(A20*cbo_http_requests+B20*funder_http_requests+A20*sms_in_segments_per_cbo)-free_requests)/1000000*price_million_requests+min_instances*price_warm_instance | F20: =MAX(0,A20*storage_mb_per_cbo/1024-free_storage_gb)*price_storage_gb | G20: =MAX(0,B20*egress_mb_per_funder/1024-free_egress_gb)*price_egress_gb | H20: =MAX(0,A20*firestore_writes_per_cbo-free_fs_writes)/100000*price_fs_write+MAX(0,A20*firestore_reads_per_cbo-free_fs_reads)/100000*price_fs_read | I20: =A20*sms_out_cost_per_cbo | J20: =A20*sms_in_cost_per_cbo | K20: =A20*azure_cost_per_cbo | L20: =A20*gemini_doc_cost_per_cbo | M20: =A20*gemini_research_cost_per_cbo | N20: =B20*gemini_search_cost_per_funder | O20: =B20*gemini_question_cost_per_funder | P20: =A20*gemini_sms_cost_per_cbo | Q20: =B20*openai_cost_per_funder | R20: =A20*claude_cost_per_cbo | S20: =MAX(0,AB20-free_search)/1000*price_search_1k | T20: =MAX(0,AA20-free_maps)/1000*price_map_1k | U20: =MAX(0,A20*geocode_updates_per_cbo-free_geocode)/1000*price_geocode_1k | V20: =SUM(C20:U20) | W20: =V20*12 | X20: =IF(A20=0,NA(),V20/A20) | Y20: =IF(V20=0,0,(I20+J20)/V20) | Z20: =IF(V20=0,0,SUM(C20:H20)/V20) | AA20: =B20*map_loads_per_funder | AB20: =A20*refreshes_per_cbo_month*searches_per_refresh+B20*audits_per_funder*searches_per_audit | AC20: =(A20*cbo_http_requests+B20*funder_http_requests+A20*sms_in_segments_per_cbo)*request_vcpu_seconds+A20*pages_per_cbo_month*page_vcpu_seconds | AD20: =free_vcpu-AC20
A21: =cbo_tier_3 | B21: =funder_tier_4 | C21: =IF(OR(A21>=step_std_at,B21>=step_std_at),price_sql_std,IF(OR(A21>=step_small_at,B21>=step_small_at),price_sql_small,price_sql_micro)) | D21: =platform_fixed_fees | E21: =MAX(0,AC21-free_vcpu)*price_vcpu+MAX(0,AC21*memory_gib-free_gib)*price_gib+MAX(0,(A21*cbo_http_requests+B21*funder_http_requests+A21*sms_in_segments_per_cbo)-free_requests)/1000000*price_million_requests+min_instances*price_warm_instance | F21: =MAX(0,A21*storage_mb_per_cbo/1024-free_storage_gb)*price_storage_gb | G21: =MAX(0,B21*egress_mb_per_funder/1024-free_egress_gb)*price_egress_gb | H21: =MAX(0,A21*firestore_writes_per_cbo-free_fs_writes)/100000*price_fs_write+MAX(0,A21*firestore_reads_per_cbo-free_fs_reads)/100000*price_fs_read | I21: =A21*sms_out_cost_per_cbo | J21: =A21*sms_in_cost_per_cbo | K21: =A21*azure_cost_per_cbo | L21: =A21*gemini_doc_cost_per_cbo | M21: =A21*gemini_research_cost_per_cbo | N21: =B21*gemini_search_cost_per_funder | O21: =B21*gemini_question_cost_per_funder | P21: =A21*gemini_sms_cost_per_cbo | Q21: =B21*openai_cost_per_funder | R21: =A21*claude_cost_per_cbo | S21: =MAX(0,AB21-free_search)/1000*price_search_1k | T21: =MAX(0,AA21-free_maps)/1000*price_map_1k | U21: =MAX(0,A21*geocode_updates_per_cbo-free_geocode)/1000*price_geocode_1k | V21: =SUM(C21:U21) | W21: =V21*12 | X21: =IF(A21=0,NA(),V21/A21) | Y21: =IF(V21=0,0,(I21+J21)/V21) | Z21: =IF(V21=0,0,SUM(C21:H21)/V21) | AA21: =B21*map_loads_per_funder | AB21: =A21*refreshes_per_cbo_month*searches_per_refresh+B21*audits_per_funder*searches_per_audit | AC21: =(A21*cbo_http_requests+B21*funder_http_requests+A21*sms_in_segments_per_cbo)*request_vcpu_seconds+A21*pages_per_cbo_month*page_vcpu_seconds | AD21: =free_vcpu-AC21
A22: =cbo_tier_3 | B22: =funder_tier_5 | C22: =IF(OR(A22>=step_std_at,B22>=step_std_at),price_sql_std,IF(OR(A22>=step_small_at,B22>=step_small_at),price_sql_small,price_sql_micro)) | D22: =platform_fixed_fees | E22: =MAX(0,AC22-free_vcpu)*price_vcpu+MAX(0,AC22*memory_gib-free_gib)*price_gib+MAX(0,(A22*cbo_http_requests+B22*funder_http_requests+A22*sms_in_segments_per_cbo)-free_requests)/1000000*price_million_requests+min_instances*price_warm_instance | F22: =MAX(0,A22*storage_mb_per_cbo/1024-free_storage_gb)*price_storage_gb | G22: =MAX(0,B22*egress_mb_per_funder/1024-free_egress_gb)*price_egress_gb | H22: =MAX(0,A22*firestore_writes_per_cbo-free_fs_writes)/100000*price_fs_write+MAX(0,A22*firestore_reads_per_cbo-free_fs_reads)/100000*price_fs_read | I22: =A22*sms_out_cost_per_cbo | J22: =A22*sms_in_cost_per_cbo | K22: =A22*azure_cost_per_cbo | L22: =A22*gemini_doc_cost_per_cbo | M22: =A22*gemini_research_cost_per_cbo | N22: =B22*gemini_search_cost_per_funder | O22: =B22*gemini_question_cost_per_funder | P22: =A22*gemini_sms_cost_per_cbo | Q22: =B22*openai_cost_per_funder | R22: =A22*claude_cost_per_cbo | S22: =MAX(0,AB22-free_search)/1000*price_search_1k | T22: =MAX(0,AA22-free_maps)/1000*price_map_1k | U22: =MAX(0,A22*geocode_updates_per_cbo-free_geocode)/1000*price_geocode_1k | V22: =SUM(C22:U22) | W22: =V22*12 | X22: =IF(A22=0,NA(),V22/A22) | Y22: =IF(V22=0,0,(I22+J22)/V22) | Z22: =IF(V22=0,0,SUM(C22:H22)/V22) | AA22: =B22*map_loads_per_funder | AB22: =A22*refreshes_per_cbo_month*searches_per_refresh+B22*audits_per_funder*searches_per_audit | AC22: =(A22*cbo_http_requests+B22*funder_http_requests+A22*sms_in_segments_per_cbo)*request_vcpu_seconds+A22*pages_per_cbo_month*page_vcpu_seconds | AD22: =free_vcpu-AC22
A23: =cbo_tier_3 | B23: =funder_tier_6 | C23: =IF(OR(A23>=step_std_at,B23>=step_std_at),price_sql_std,IF(OR(A23>=step_small_at,B23>=step_small_at),price_sql_small,price_sql_micro)) | D23: =platform_fixed_fees | E23: =MAX(0,AC23-free_vcpu)*price_vcpu+MAX(0,AC23*memory_gib-free_gib)*price_gib+MAX(0,(A23*cbo_http_requests+B23*funder_http_requests+A23*sms_in_segments_per_cbo)-free_requests)/1000000*price_million_requests+min_instances*price_warm_instance | F23: =MAX(0,A23*storage_mb_per_cbo/1024-free_storage_gb)*price_storage_gb | G23: =MAX(0,B23*egress_mb_per_funder/1024-free_egress_gb)*price_egress_gb | H23: =MAX(0,A23*firestore_writes_per_cbo-free_fs_writes)/100000*price_fs_write+MAX(0,A23*firestore_reads_per_cbo-free_fs_reads)/100000*price_fs_read | I23: =A23*sms_out_cost_per_cbo | J23: =A23*sms_in_cost_per_cbo | K23: =A23*azure_cost_per_cbo | L23: =A23*gemini_doc_cost_per_cbo | M23: =A23*gemini_research_cost_per_cbo | N23: =B23*gemini_search_cost_per_funder | O23: =B23*gemini_question_cost_per_funder | P23: =A23*gemini_sms_cost_per_cbo | Q23: =B23*openai_cost_per_funder | R23: =A23*claude_cost_per_cbo | S23: =MAX(0,AB23-free_search)/1000*price_search_1k | T23: =MAX(0,AA23-free_maps)/1000*price_map_1k | U23: =MAX(0,A23*geocode_updates_per_cbo-free_geocode)/1000*price_geocode_1k | V23: =SUM(C23:U23) | W23: =V23*12 | X23: =IF(A23=0,NA(),V23/A23) | Y23: =IF(V23=0,0,(I23+J23)/V23) | Z23: =IF(V23=0,0,SUM(C23:H23)/V23) | AA23: =B23*map_loads_per_funder | AB23: =A23*refreshes_per_cbo_month*searches_per_refresh+B23*audits_per_funder*searches_per_audit | AC23: =(A23*cbo_http_requests+B23*funder_http_requests+A23*sms_in_segments_per_cbo)*request_vcpu_seconds+A23*pages_per_cbo_month*page_vcpu_seconds | AD23: =free_vcpu-AC23
A24: =cbo_tier_4 | B24: =funder_tier_1 | C24: =IF(OR(A24>=step_std_at,B24>=step_std_at),price_sql_std,IF(OR(A24>=step_small_at,B24>=step_small_at),price_sql_small,price_sql_micro)) | D24: =platform_fixed_fees | E24: =MAX(0,AC24-free_vcpu)*price_vcpu+MAX(0,AC24*memory_gib-free_gib)*price_gib+MAX(0,(A24*cbo_http_requests+B24*funder_http_requests+A24*sms_in_segments_per_cbo)-free_requests)/1000000*price_million_requests+min_instances*price_warm_instance | F24: =MAX(0,A24*storage_mb_per_cbo/1024-free_storage_gb)*price_storage_gb | G24: =MAX(0,B24*egress_mb_per_funder/1024-free_egress_gb)*price_egress_gb | H24: =MAX(0,A24*firestore_writes_per_cbo-free_fs_writes)/100000*price_fs_write+MAX(0,A24*firestore_reads_per_cbo-free_fs_reads)/100000*price_fs_read | I24: =A24*sms_out_cost_per_cbo | J24: =A24*sms_in_cost_per_cbo | K24: =A24*azure_cost_per_cbo | L24: =A24*gemini_doc_cost_per_cbo | M24: =A24*gemini_research_cost_per_cbo | N24: =B24*gemini_search_cost_per_funder | O24: =B24*gemini_question_cost_per_funder | P24: =A24*gemini_sms_cost_per_cbo | Q24: =B24*openai_cost_per_funder | R24: =A24*claude_cost_per_cbo | S24: =MAX(0,AB24-free_search)/1000*price_search_1k | T24: =MAX(0,AA24-free_maps)/1000*price_map_1k | U24: =MAX(0,A24*geocode_updates_per_cbo-free_geocode)/1000*price_geocode_1k | V24: =SUM(C24:U24) | W24: =V24*12 | X24: =IF(A24=0,NA(),V24/A24) | Y24: =IF(V24=0,0,(I24+J24)/V24) | Z24: =IF(V24=0,0,SUM(C24:H24)/V24) | AA24: =B24*map_loads_per_funder | AB24: =A24*refreshes_per_cbo_month*searches_per_refresh+B24*audits_per_funder*searches_per_audit | AC24: =(A24*cbo_http_requests+B24*funder_http_requests+A24*sms_in_segments_per_cbo)*request_vcpu_seconds+A24*pages_per_cbo_month*page_vcpu_seconds | AD24: =free_vcpu-AC24
A25: =cbo_tier_4 | B25: =funder_tier_2 | C25: =IF(OR(A25>=step_std_at,B25>=step_std_at),price_sql_std,IF(OR(A25>=step_small_at,B25>=step_small_at),price_sql_small,price_sql_micro)) | D25: =platform_fixed_fees | E25: =MAX(0,AC25-free_vcpu)*price_vcpu+MAX(0,AC25*memory_gib-free_gib)*price_gib+MAX(0,(A25*cbo_http_requests+B25*funder_http_requests+A25*sms_in_segments_per_cbo)-free_requests)/1000000*price_million_requests+min_instances*price_warm_instance | F25: =MAX(0,A25*storage_mb_per_cbo/1024-free_storage_gb)*price_storage_gb | G25: =MAX(0,B25*egress_mb_per_funder/1024-free_egress_gb)*price_egress_gb | H25: =MAX(0,A25*firestore_writes_per_cbo-free_fs_writes)/100000*price_fs_write+MAX(0,A25*firestore_reads_per_cbo-free_fs_reads)/100000*price_fs_read | I25: =A25*sms_out_cost_per_cbo | J25: =A25*sms_in_cost_per_cbo | K25: =A25*azure_cost_per_cbo | L25: =A25*gemini_doc_cost_per_cbo | M25: =A25*gemini_research_cost_per_cbo | N25: =B25*gemini_search_cost_per_funder | O25: =B25*gemini_question_cost_per_funder | P25: =A25*gemini_sms_cost_per_cbo | Q25: =B25*openai_cost_per_funder | R25: =A25*claude_cost_per_cbo | S25: =MAX(0,AB25-free_search)/1000*price_search_1k | T25: =MAX(0,AA25-free_maps)/1000*price_map_1k | U25: =MAX(0,A25*geocode_updates_per_cbo-free_geocode)/1000*price_geocode_1k | V25: =SUM(C25:U25) | W25: =V25*12 | X25: =IF(A25=0,NA(),V25/A25) | Y25: =IF(V25=0,0,(I25+J25)/V25) | Z25: =IF(V25=0,0,SUM(C25:H25)/V25) | AA25: =B25*map_loads_per_funder | AB25: =A25*refreshes_per_cbo_month*searches_per_refresh+B25*audits_per_funder*searches_per_audit | AC25: =(A25*cbo_http_requests+B25*funder_http_requests+A25*sms_in_segments_per_cbo)*request_vcpu_seconds+A25*pages_per_cbo_month*page_vcpu_seconds | AD25: =free_vcpu-AC25
A26: =cbo_tier_4 | B26: =funder_tier_3 | C26: =IF(OR(A26>=step_std_at,B26>=step_std_at),price_sql_std,IF(OR(A26>=step_small_at,B26>=step_small_at),price_sql_small,price_sql_micro)) | D26: =platform_fixed_fees | E26: =MAX(0,AC26-free_vcpu)*price_vcpu+MAX(0,AC26*memory_gib-free_gib)*price_gib+MAX(0,(A26*cbo_http_requests+B26*funder_http_requests+A26*sms_in_segments_per_cbo)-free_requests)/1000000*price_million_requests+min_instances*price_warm_instance | F26: =MAX(0,A26*storage_mb_per_cbo/1024-free_storage_gb)*price_storage_gb | G26: =MAX(0,B26*egress_mb_per_funder/1024-free_egress_gb)*price_egress_gb | H26: =MAX(0,A26*firestore_writes_per_cbo-free_fs_writes)/100000*price_fs_write+MAX(0,A26*firestore_reads_per_cbo-free_fs_reads)/100000*price_fs_read | I26: =A26*sms_out_cost_per_cbo | J26: =A26*sms_in_cost_per_cbo | K26: =A26*azure_cost_per_cbo | L26: =A26*gemini_doc_cost_per_cbo | M26: =A26*gemini_research_cost_per_cbo | N26: =B26*gemini_search_cost_per_funder | O26: =B26*gemini_question_cost_per_funder | P26: =A26*gemini_sms_cost_per_cbo | Q26: =B26*openai_cost_per_funder | R26: =A26*claude_cost_per_cbo | S26: =MAX(0,AB26-free_search)/1000*price_search_1k | T26: =MAX(0,AA26-free_maps)/1000*price_map_1k | U26: =MAX(0,A26*geocode_updates_per_cbo-free_geocode)/1000*price_geocode_1k | V26: =SUM(C26:U26) | W26: =V26*12 | X26: =IF(A26=0,NA(),V26/A26) | Y26: =IF(V26=0,0,(I26+J26)/V26) | Z26: =IF(V26=0,0,SUM(C26:H26)/V26) | AA26: =B26*map_loads_per_funder | AB26: =A26*refreshes_per_cbo_month*searches_per_refresh+B26*audits_per_funder*searches_per_audit | AC26: =(A26*cbo_http_requests+B26*funder_http_requests+A26*sms_in_segments_per_cbo)*request_vcpu_seconds+A26*pages_per_cbo_month*page_vcpu_seconds | AD26: =free_vcpu-AC26
A27: =cbo_tier_4 | B27: =funder_tier_4 | C27: =IF(OR(A27>=step_std_at,B27>=step_std_at),price_sql_std,IF(OR(A27>=step_small_at,B27>=step_small_at),price_sql_small,price_sql_micro)) | D27: =platform_fixed_fees | E27: =MAX(0,AC27-free_vcpu)*price_vcpu+MAX(0,AC27*memory_gib-free_gib)*price_gib+MAX(0,(A27*cbo_http_requests+B27*funder_http_requests+A27*sms_in_segments_per_cbo)-free_requests)/1000000*price_million_requests+min_instances*price_warm_instance | F27: =MAX(0,A27*storage_mb_per_cbo/1024-free_storage_gb)*price_storage_gb | G27: =MAX(0,B27*egress_mb_per_funder/1024-free_egress_gb)*price_egress_gb | H27: =MAX(0,A27*firestore_writes_per_cbo-free_fs_writes)/100000*price_fs_write+MAX(0,A27*firestore_reads_per_cbo-free_fs_reads)/100000*price_fs_read | I27: =A27*sms_out_cost_per_cbo | J27: =A27*sms_in_cost_per_cbo | K27: =A27*azure_cost_per_cbo | L27: =A27*gemini_doc_cost_per_cbo | M27: =A27*gemini_research_cost_per_cbo | N27: =B27*gemini_search_cost_per_funder | O27: =B27*gemini_question_cost_per_funder | P27: =A27*gemini_sms_cost_per_cbo | Q27: =B27*openai_cost_per_funder | R27: =A27*claude_cost_per_cbo | S27: =MAX(0,AB27-free_search)/1000*price_search_1k | T27: =MAX(0,AA27-free_maps)/1000*price_map_1k | U27: =MAX(0,A27*geocode_updates_per_cbo-free_geocode)/1000*price_geocode_1k | V27: =SUM(C27:U27) | W27: =V27*12 | X27: =IF(A27=0,NA(),V27/A27) | Y27: =IF(V27=0,0,(I27+J27)/V27) | Z27: =IF(V27=0,0,SUM(C27:H27)/V27) | AA27: =B27*map_loads_per_funder | AB27: =A27*refreshes_per_cbo_month*searches_per_refresh+B27*audits_per_funder*searches_per_audit | AC27: =(A27*cbo_http_requests+B27*funder_http_requests+A27*sms_in_segments_per_cbo)*request_vcpu_seconds+A27*pages_per_cbo_month*page_vcpu_seconds | AD27: =free_vcpu-AC27
